Workbook
Name SegmentaciónDeDatos_Hoja_Impresión_Clte.: #N/A
Name SegmentaciónDeDatos_Hoja_Impresión_Compras.: #N/A
Name SegmentaciónDeDatos_Modelos: #N/A

Sheet BD Total
A1: Item | B1: Categorias | C1: Unidad | D1: P. Unitario real | E1: Nombre de ppto donde se saco la info | F1: Hoja Impresión Clte. | G1: Hoja Impresión Compras. | H1: Empresa
A2: Calefont 7 litros | B2: Adicionales | C2: Unidad | D2: 112600 | E2: nueva cliente javier 01122025 | F2: Si | G2: Si
A3: Calefont Tiro Natural 11 litros | B3: Adicionales | C3: Unidad | D3: 159990 | E3: nueva solo por un cliente | F3: Si | G3: Si
A4: Closet 250 x 230 | B4: Adicionales | C4: Unidad | D4: 800000 | E4: Nueva javier 20112025 | F4: Si | G4: Si | H4: Rogelio
A5: Closet 300 X 230 | B5: Adicionales | C5: Unidad | D5: 800000 | F5: Si | G5: Si | H5: Rogelio
A6: Closet 320 x 230 6 cajoneras Blanco | B6: Adicionales | C6: Unidad | D6: 850000 | F6: Si | G6: Si | H6: Rogelio
A7: Closet 320 x 230 6 cajoneras color a eleccion | B7: Adicionales | C7: Unidad | D7: 950000 | F7: Si | G7: Si | H7: Rogelio
A8: Closet 320 x 230 6 cajoneras puertas de color | B8: Adicionales | C8: Unidad | D8: 900000 | F8: Si | G8: Si | H8: Rogelio
A9: Closet de 2.70 x 2,40 | B9: Adicionales | C9: Unidad | D9: 1000000 | E9: Javier24082025 | F9: Si | G9: Si
A10: Closet de Cuatro cuerpos + cajoneras - Piso a techo 2,20x2,30 | B10: Adicionales | C10: Unidad | D10: 800000 | E10: Nueva categoria 17062025 | F10: Si | G10: Si
A11: Closet de Tres cuerpos - Piso a techo | B11: Adicionales | C11: Unidad | D11: 350000 | E11: Nueva categoria 23032025 | F11: Si | G11: Si
A12: Closet Desde 130 A 160 X 230 | B12: Adicionales | C12: Unidad | D12: 350000 | F12: No | G12: Si | H12: Rogelio
A13: Conexión de Lavadora | B13: Adicionales | C13: Unidad | D13: 50000 | E13: Nueva categoria 23032025 | F13: Si | G13: Si
A14: Enchufe Adicional | B14: Adicionales | C14: Unidad | D14: 40000 | E14: Categorias adicionales 25112025 | F14: Si | G14: Si
A15: Escalera Interior | B15: Adicionales | C15: Unidad | D15: 1500000 | E15: nueva javier envia valores 230602025 | F15: Si | G15: Si
A16: Gabinete para Calefont 11 litros | B16: Adicionales | C16: Unidad | D16: 70400 | E16: nueva solo por un cliente | F16: Si | G16: Si
A17: Iluminacion Adicional interior o exterior | B17: Adicionales | C17: Unidad | D17: 50000 | E17: Categorias adicionales 18032025 | F17: Si | G17: Si
A18: Informe T1 20 Pies | B18: Adicionales | C18: Unidad | D18: 200000 | E18: Nueva categoria 17062025 | F18: Si | G18: Si
A19: Informe T1 40 Pies | B19: Adicionales | C19: Unidad | D19: 400000 | E19: Nueva categoria 17062025 | F19: Si | G19: Si
A20: Mano de Obra Calefont | B20: Adicionales | C20: Unidad | D20: 40000 | E20: nueva javier envia valores 240402025 | F20: Si | G20: Si
A21: Mano de Obra Gas | B21: Adicionales | C21: Unidad | D21: 50000 | E21: nueva javier envia valores 240402025 | F21: Si | G21: Si
A22: Mano de Obra Instalacion Revestimiento Exterior fallada y parte trasera | B22: Adicionales | C22: m2 | D22: 4000 | E22: Categorias adicionales 18032025 | F22: Si | G22: Si
A23: Mano de Obra Pintura | B23: Adicionales | C23: m2 | D23: 2500 | E23: Categorias adicionales 18032025 | F23: Si | G23: Si
A24: Mano de Obra Tabiqueria y recubrimiento Laterales sin Puerta | B24: Adicionales | C24: m2 | D24: 8000 | E24: Categorias adicionales 18032025 | F24: Si | G24: Si
A25: Piso Diamantado aluminio 1,5mm 100x300 | B25: Adicionales | C25: Unidad | D25: =90000/1.19 -> 75630.252 | E25: Nueva javier 10122025 | F25: Si | G25: Si
A26: Punto de Agua | B26: Adicionales | C26: Unidad | D26: 60000 | E26: Categorias adicionales 13052025 | F26: Si | G26: Si
A27: Separador de ambiente | B27: Adicionales | C27: Unidad | D27: 300000 | E27: nueva valor entregado javier 24092025 | F27: Si | G27: Si
A28: Visita Técnica en RM | B28: Adicionales | C28: Unidad | D28: 70000 | E28: Nueva categoria 25062025 | F28: Si | G28: Si
A29: Walking Closet 170X 230 - 140X230 Melamina Blanca | B29: Adicionales | C29: Unidad | D29: 600000 | F29: Si | G29: Si | H29: Rogelio
A30: Walking Closet 170X 230 - 140X230 Melamina Colores a eleccion | B30: Adicionales | C30: Unidad | D30: 700000 | F30: Si | G30: Si | H30: Rogelio
A31: Walking Closet 200 largo x 2,40 alto x 0,50 de profundidad | B31: Adicionales | C31: Unidad | D31: 540000 | E31: nuevo andrea 19012026 | F31: Si | G31: Si
A32: Aislante Termico Fisiterm 55mm x 2,4 15 mts | B32: Aislación | C32: M2 | D32: 39033 | E32: Nuevo | F32: Si | G32: Si
A33: Poliuretano Proyectado | B33: Aislación | C33: m2 | D33: 8000 | E33: actualizacion alan 17032025 | F33: Si | G33: Si
A34: Poliuretano Proyectado 120 m2 | B34: Aislación | C34: Pack | D34: 1904000 | E34: nueva 02022026 | F34: Si | G34: No
A35: Poliuretano Proyectado 30 m2 | B35: Aislación | C35: Pack | D35: 768000 | E35: nueva 02022026 | F35: Si | G35: No
A36: Poliuretano Proyectado 45 m2 | B36: Aislación | C36: Pack | D36: 960000 | E36: nueva 02022026 | F36: Si | G36: No
A37: Poliuretano Proyectado 60 m2 | B37: Aislación | C37: Pack | D37: 1216000 | E37: nueva 02022026 | F37: Si | G37: No
A38: Poliuretano Proyectado 90 m2 | B38: Aislación | C38: Pack | D38: 1584000 | E38: nueva 02022026 | F38: Si | G38: No
A39: Poliuretano Proyectado Base | B39: Aislación | C39: M2 | D39: 8000 | E39: actualizacion alan 17032025 | F39: Si | G39: Si
A40: Poliuretano Proyectado Base 120 m2 | B40: Aislación | C40: Pack | D40: 960000 | E40: nueva 02022026 | F40: Si | G40: No
...

Sheet Desplegables
A1: Personalizado | B1: Adicionales | C1: Aislación | D1: Baño | E1: Climatización | F1: Cocina | G1: Container | H1: Iluminación | I1: Living | J1: Electricidad | K1: Fachada | L1: Fundiciones | M1: Grifería | N1: Obras | O1: Pintura | P1: Piso | Q1: Puerta | R1: Sanitario | S1: Tabiquería | T1: Techo | U1: Terraza | V1: Transporte | W1: Unión | X1: Varios | Y1: Ventana
A2: Adicionales | B2: Aislante Termico Fisiterm 55mm x 2,4 15 mts | C2: Aislante Termico Fisiterm 55mm x 2,4 15 mts | D2: Angulo Aluminio 10x10 | E2: Estufa A leña Bosca Eco | F2: Campana + Encimera Electrica 4 Platos + Horno Electrico | G2: Container Maritimo Estandar 6 X 2,44 X 2,59 - 20 Pies | H2: Focos Led Pack 3 de Lamparas 30w | I2: Mueble muro tv living | J2: Abrazaderas Metalicas | K2: Angulo wpc Dark Grey 2,40 x 55 x 55 | L2: Cadena Metalcom estructural 150x9.2mm 4.5 M | M2: Llaves Monomando - Ducha | N2: Base de Cemento 40x40x40 | O2: Barniz Cerestain | P2: Espuma Niveladora 10 metros | Q2: Alero Liso 100x120 Transparente | R2: Codo 20mm 90° PPR Koalition | S2: Angulo gris de aluminio 32x32 2,5 mm 2,5 metros | T2: Plancha fierro laminado 0,5 mm x 1x3m | U2: Cubrezocalo para plancha policarbonato | V2: Carga y descarga 3 contenedores | W2: Espuma Poliuretano | X2: Andamio 1 Cuerpo x 1,80 | Y2: Ventana 1,50 x 2,33
A3: Aislación | B3: Calefont 7 litros | C3: Poliuretano Proyectado | D3: Barra Pasamano Muro 50cm | F3: Campana 2 platos | G3: Container Maritimo HC 12 x 2,44 x 2,89 - 40 Pies | H3: Iluminación Exterior | J3: Automático 10 Amperes | K3: Plancha lam cal 3,0x1000xs300mm | L3: Caja de Tornillos 6x2" | M3: Llaves Monomando - Lava Manos | O3: Barniz Con Poliuretano 1/4 Puerta Exterior | P3: Piso DECK WPC Color Madera XFD002 | Q3: Bisagra aluminio 1, 45 mm satinado | R3: Codo 20Mm Ppr | S3: Angulos 50 X 50 2Mm | U3: Liston Pino 1 x 2" | V3: Carga y descarga 4 contenedores en Alhue | W3: Perfil Pletina 50 X 3Mm 6M | X3: Arriendo Taller De Construcción | Y3: Ventana 300 X 227
A4: Baño | B4: Calefont Tiro Natural 11 litros | C4: Poliuretano Proyectado 120 pies | D4: Columna de Ducha Baño mono mando | F4: Campana Rectangular Acero Inox 90 cm Maigas 90M17 - oferta 07082025 | G4: Container Maritimo Estandar 12 x 2,44 x 2,59 - 40 Pies | H4: Iluminación Interior Led Calida 1800Wts | J4: Automatico 16 Amperes | K4: Plancha lam frio 0,8x1000xs300mm | L4: Hormigón H25 6m3 | M4: Llaves Monomando - Lava Platos | O4: Diluyente Duco | P4: Piso Diamantado aluminio 1,5mm 100x300 | Q4: Bisagras | R4: Codo HE 20" 1/2 PPR Koalition | S4: Canal 80 x 40 2mm x 6 metros | U4: Piso Deck PVC WPC madera + Incluye insumos | W4: Perfil Rectangular Acero 100X150 X 3 mm 6m | X4: Baño Quimico | Y4: Ventana 70/30 de 3000 x 200 con tres rieles
A5: Climatización | B5: Closet 250 x 230 | C5: Poliuretano Proyectado 30 pies | D5: Ducha Telefono | F5: Cocina a gas 2 platos | G5: Container Maritimo HC 13,716 x 2,44 x 2,89 - 45 Pies | H5: Iluminación Interior Led Fria 1800Wts | J5: Automatico 25 Amperes | K5: Siding Metalico - Plancha 5,85 x 0,38 | L5: Mano de Obra Fabricación Fundaciones | O5: Pintura Anticorrosivo (Galon) | P5: Piso Flotante Alto Trafico 8mm | Q5: Bisagras Puerta Exterior | R5: Conexión Sanitaria T 110mm | S5: Canal Cielo 20X 25 0,4mm x 3m | U5: Policarbonato alveolar 2100 x 5800 x 6 mm | W5: Unión En Terreno por Contenedor | X5: Bono Cumplimiento meta | Y5: Ventana Aluminio Corredera 100x100 cm
A6: Cocina | B6: Closet 300 X 230 | C6: Poliuretano Proyectado 45 pies | D6: Espejo Cuadrado Retroiluminado 50X70 | F6: Encimera Vitrocerámica de 4 Platos Negra | G6: Container Maritimo Reefer 12 x 2,44 x 2,89 - 40 Pies | H6: Iluminiación Interior Decroit con Led 5w | J6: Bipolar | K6: Sinding Metalico Negro o Gris 290x38,3x1,6cm | L6: Plancha de acero laminado para Flanches 1000x 3000 10mm. | O6: Pintura Anticorrosivo (Tineta) | P6: Piso Vinilico Tipo Click 6 Mm | Q6: Cerrojo Carcelero 8 zincado | R6: Conexión Sanitaria T 110mm a 40mm | S6: Canal Estructural U 2X4 0,85 mm | X6: Camioneta Alan Bencina Tag Y Mantencion | Y6: Ventana Aluminio Corredera 150x150
A7: Container | B7: Closet 320 x 230 6 cajoneras Blanco | C7: Poliuretano Proyectado 60 pies | D7: Espejo Redondo Retroiluminado 60 Diametro | F7: Encinera electrica 2 platos | H7: Luces Empotrada 22 mm | J7: Cable 924 | K7: Sinding Metalico Perfil de Inicio o Termino | L7: Tablero terciado estructural 18mm | O7: Pintura Anticorrosivo (Tineta) - 20 pies | P7: Piso Vinilico Tipo Click 9mm | Q7: Chapa Puerta | R7: Conexión Sanitaria T 40mm | S7: Canal Normal 61X20X05Mm 3Mt | X7: Camioneta Miguel trabajo en terreno | Y7: Ventana Aluminio Fija 70X160
A8: Electricidad | B8: Closet 320 x 230 6 cajoneras color a eleccion | C8: Poliuretano Proyectado 90 pies | D8: Esquinero Marmolizado | F8: Extencion Mueble de cocina | H8: Luces Estanco Led 1X10W | J8: Cable eva 4 mm (pack 3 rollos 3 colores 10metros c/u) | K8: Smart Panel | O8: Pintura Esmalte al Agua - Color a eleccion | P8: Plancha fibrocemento lisa 5mm 120x240 cm | Q8: Chapa Puerta cangrejo | R8: Conexiones Sanitarias Codo 110mm | S8: Canal U 62x20x0,50 mm 3m | X8: Conexión de Gas, Encimera y Calefont | Y8: Ventana aluminio Paño fijo línea 42 30x160
A9: Fachada | B9: Closet 320 x 230 6 cajoneras puertas de color | C9: Poliuretano Proyectado Base | D9: Extractor 16x16 cm 20wts | F9: Horno empotrado | H9: Luz Piloto | J9: Cableado 1,5 En Eva - Rollo 50m | K9: WPC Exterior | O9: Pintura Esmalte al Agua - Color a eleccion - 20 pies | P9: Porcelanato Baku Haya 30x120 cm 1.80m2 | Q9: Chapa Puerta Exterio Chapa De Seguridad | R9: Conexiones Sanitarias Codo 40mm | S9: Canal U 62x25x0,85 mm 6m | X9: Corte y soldadura de contenedor | Y9: Ventana Aluminio Proyectante 0,5X 1
A10: Fundiciones | B10: Closet de 2.70 x 2,40 | C10: Poliuretano Proyectado Base 120 pies | D10: Extractor Aire baño 4" | F10: isla 100X160X90 + muebles base | J10: Cableado 2,5 En Eva - Rollo 50m | O10: Pintura Esmalte Al Agua Color Blanco | P10: Porcelanato Camper beige 60x60 | Q10: Kit Puerta Granero | R10: Copla 20mm PPR Koalition | S10: Carga Gas Soldadura Compresion (10m3) | X10: Cortes de contenedor 20 pies | Y10: Ventana Aluminio Proyectante 1,5 X 0,5
A11: Grifería | B11: Closet de Cuatro cuerpos + cajoneras - Piso a techo 2,20x2,30 | C11: Poliuretano Proyectado Base 30 pies | D11: Fragüe cerámico 1 kg | F11: Isla con cubierta y patas de cuarzo | J11: Caja 100 x 65 x 100 mm Estanca Blanco Mec | O11: Pintura Esmalte Al Agua Color Blanco - 20 pies | P11: Protector de madera transparente | Q11: Mampara Pino Radiata 4 Luces 30x200 | R11: Coplas 20Mm Ppr | S11: Cielo Perfil AT 20X 25X 0,4mm 3metros | X11: Electricidad Maestranza 20 pies | Y11: Ventana Aluminio Proyectante 200X50 + Ventana Fija 200x150
A12: Iluminación | B12: Closet de Tres cuerpos - Piso a techo | C12: Poliuretano Proyectado Base 45 pies | D12: Lavamanos al aire | F12: Isla madera potformada 1,20X60 | J12: Caja De Distribución | O12: Pintura Exterior Esmalte Sintetico - Color a Eleccion | Q12: Marco Puerta | R12: Desagues Ducha | S12: Cielo Portante 40X18X10X0,5Mm 3Mts | X12: Electricidad Maestranza 40 pies | Y12: Ventana Alumino Fija 0,85 x 1,30
A13: Living | B13: Closet Desde 130 A 160 X 230 | C13: Poliuretano Proyectado Base 60 pies | D13: Lavamanos pedestal | F13: Isla móvil con cubierta de cuarzo 0,60 x 1,20 | J13: Caja estanca exterior | O13: Pintura Exterior Esmalte Sintetico - Color a Eleccion - 20 pies | Q13: Marco Puerta Exterior | R13: Desagues Lavaplatos | S13: Cinta malla para yeso | X13: Firma contrato | Y13: Ventana Celosía (Baño) 0,46 X 0,55
A14: Obras | B14: Conexión de Lavadora | C14: Poliuretano Proyectado Base 90 pies | D14: Mampara ajustable 6mm 135 -150x185cm | F14: Lavaplatos Doble | J14: Cinta Aislante | O14: Pintura Exterior Esmalte Sintetico - Color Blanco | Q14: Picaporte Carcelero dorado 30cm | R14: Desgues Lavamos | S14: Cornisas | X14: Flete Contenedor | Y14: Ventana Corredera 1,00 X 0,50 Termopanel Pvc
A15: Pintura | B15: Descuento Especial Puerta | D15: Mampara eko corredera 120x90 cm | F15: Lavaplatos Embutido | J15: Conectores Conicos 1,5 | O15: Pintura Exterior Esmalte Sintetico - Color Blanco - 20 pies | Q15: Pomel 3/4 - 2 unidades | R15: Flexibles | S15: Cuarto rodon 13 | X15: Fletes General | Y15: Ventana Corredera 1,50 X 1,50 Termopanel Pvc Bl/Fol Madera/ Negro
A16: Piso | B16: Enchufe Adicional | D16: Mueble Vanitorio 71 cm Fiumo Vessanti | F16: Lavaplatos Termolaminado | J16: Conectores Conicos 2,5 | O16: Pintura impermeable acrílica Sikafill | Q16: Puerta Interior Sinfonia 65 | R16: Kit De Lavaplatos | S16: Cuarto rodon 19 | X16: Grua Orquilla | Y16: Ventana Corredera 100x100 Linea 5000
A17: Puerta | B17: Escalera Interior | D17: Mueble Vanitorio Aereo 38,4 cm BN Almendra | F17: Llave gas encimera | J17: Conectores Terminales 20Mm | O17: Pintura Latex | Q17: Puerta Abatible doble aluminio PVC 1,40 x 2,00 | R17: Kit Instalacion Sanitario Wc | S17: Disco De Corte | X17: Limpiza entrega de proyecto | Y17: Ventana Corredera 150 X 100
A18: Sanitario | B18: Gabinete para Calefont 11 litros | D18: Mueble Vanitorio dos puertas 100cm Khari duna Tuhome | F18: Mesa de desayuno 130x60 | J18: Diferenciales De 25 O 32 Amperes | O18: Pintura Latex - 20 pies | Q18: Puerta Abatible doble Termopanel PVC 1,40 x 2,00 | R18: kit Lavaplatos empotrable (sifones, llaves y accesorios) | S18: Esquinero metalcom 30x30x 0,4mm 240 | X18: Mano de Obra 20 Pies | Y18: Ventana corredera 150x40
A19: Tabiquería | B19: Iluminacion Adicional interior o exterior | D19: Mueble Vanitorio Lille 61X45,6 cm Lenga mas cubierta | F19: Mesón de cocina cubierta de cuarzo 2200 mm | J19: Enchufe Simple 16 ap | O19: Rodillos Brochas Cinta Maskin Diluyente | Q19: Puerta Blanca Milano MDF 80cm | R19: Lavamanos | S19: Esquinero Pino 30X30 | X19: Mano de Obra 40 Pies | Y19: Ventana corredera 170x200
A20: Techo | B20: Informe T1 20 Pies | D20: Mueble Vanitorio Sophie 121x 46,5 cm lenga + Cubierta | F20: Mueble base de cocina 1,50 | J20: Enchufes Dobles | O20: Sellado Madera Sipa Acabado Satinado color incoloro | Q20: Puerta de seguridad exterior | R20: Sifon Lavamanos | S20: Esquinero Tapa Canto 16mm x 250 Aluminio | X20: Mano de Obra 45 Pies | Y20: Ventana Corredera 2,00 X 1,50
A21: Terraza | B21: Informe T1 40 Pies | D21: Muros Interiores Pvc Marmolizado | F21: Mueble de Cocina 2 ,20 metros | J21: Enchufes Dobles Ip65 | Q21: Puerta de seguridad kit wintec | R21: Terminal HE 20Mm Ppr | S21: Estructura impregnada 2x6 cepillado 41x138 mm 4.8m | X21: Mano de Obra 60 Pies | Y21: Ventana Corredera 2,50 X 0,50 Termopanel Pvc - Madera/ Nogla/ Caoba/ Blanco
A22: Transporte | B22: Mano de Obra Calefont | D22: Perfil T para Marmolizado | F22: Mueble de Cocina 2 ,20 metros + Isla | J22: Fruler 1,5 | Q22: Puerta Enchapada Capri | R22: Terminal Hi 20Mm Ppr | S22: Estructural C 2X3" 085Mm 2,4 | X22: Mano de Obra 40 Pies altura 2,50 metros | Y22: Ventana corredera 200x0,50
A23: Unión | B23: Mano de Obra Gas | D23: Porcelanato Blanco Brillante 60x60cm | F23: Mueble De Cocina 2 Metros + Isla Movil ( Encimera 2 Platos Electricos + Horno Electrico + Muebles Aereos) | J23: Fruler 2,5 | Q23: Puerta Exterior Bio Bio 100x200 | R23: Tuberia multicapa Fusion PN16 20mm 3Mts | S23: Extructura Tina (Completo) | X23: Mano de Obra Especial | Y23: Ventana Corredera 200x230
A24: Varios | B24: Mano de Obra Instalacion Revestimiento Exterior fallada y parte trasera | D24: Porcelanato color Haya WF61515 15x60 cm | F24: Mueble De Cocina 2 Metros lavaplatos ( Encimera 4 Platos Electricos + Horno Electrico + Muebles Aereo+ campana) | J24: Fusible 25 Amperes | Q24: Puerta Exterior Italia Radiata 60x200 | R24: Tuberia Sanitaria 110Mm 3Metros | S24: Fisitell Arriendo / Trato | X24: Mano de Obra Grateado | Y24: Ventana corredera 250x150
A25: Ventana | B25: Mano de Obra Pintura | D25: Receptáculo 130x70 | F25: Mueble de cocina Cub Cuarzo 3,20 mts + Aereo+Encimera+horno+Campana+ Isla Cuarzo | J25: Interruptor 915 | Q25: Puerta Exterior Lauca 70x200 | R25: Tuberia Sanitaria 110Mm 6Metros | S25: Golilla plana corriente 1/4" 4 unidades | X25: Mano de Obra modular 3x12 | Y25: Ventana Corredera 300 x 200
B26: Mano de Obra Tabiqueria y recubrimiento Laterales sin Puerta | D26: Receptáculo 130x80 | F26: Mueble De Cocina Cub Quarzo ( 2M ) + Aereo + Encimera Gas + Campana + Horno Empótrado | J26: Interruptor triple (9/32) 10 A Blanco Genesis | Q26: Puerta Exterior Millenium 90x200 + Kit (Barniz, sellado y protector) | R26: Tuberia Sanitaria 40Mm 3Metros | S26: Guardapolvos | X26: Mano de Obra Planta Libre | Y26: Ventana corredera 400x 230
B27: Poliuretano Proyectado | D27: Receptaculo 130x80 chc | F27: Mueble De Cocina Cub Quarzo (3,20) | J27: Interruptores 912 | Q27: Puerta Exterior Pino Oregon | R27: Union T PPR 20Mm | S27: Guardapolvos pvc | X27: Mano de obra porcelanato | Y27: Ventana Corredera con chapa 300 x 200
B28: Punto de Agua | D28: Sala de baño 30.5 cm ( lavamanos y wc) | F28: Mueble de cocina cubierta de cuazo 3,20 muebles inferiores | J28: Interruptores 924 | Q28: Puerta Exterior Pino Rabiata Italia 80X200 | R28: Vinilit Sanitario | S28: Lijas de madera 100 | X28: Mano de obra protecciones | Y28: Ventana corredera con chapa 400x 230
B29: Separador de ambiente | D29: Teflon | F29: Mueble de cocina tipo isla + meson de desayuno | J29: Regleta Para Tablero | Q29: Puerta Granero x2 Mirador (Oregón) | S29: Lijas de madera 120 | X29: Mano de obra puerta exterior lata contenedor | Y29: Ventana corredera de 200 x 150
B30: Visita Técnica en RM | D30: Termo eléctrico 100 litros | F30: Mueble de cocina, Cub. Quarzo (3m) + Aereo + Horno, Encimera y Campana +mesa desayuno 40 x 140 | J30: Tablero Embutido Electrico 12 Puestos | Q30: Puerta Interior MDF 70x210 cm Azapa Blanco | S30: Malla mosquitera galvanizada | X30: Mano de Obra Terraza | Y30: Ventana Corredera termopanel 150x50
B31: Walking Closet 170X 230 - 140X230 Melamina Blanca | D31: Tina 70X140 cm HY Blanco Norglas | F31: Tubo Campana corrugado aluminio 5" | J31: Tablero Embutido Electrico 24 Puestos | Q31: Puerta Interior Sinfonia 70 | S31: Masilla Base | X31: Posventa 20 pies | Y31: Ventana Corredera Termopanel PVC 2,00 X 1,50
B32: Walking Closet 170X 230 - 140X230 Melamina Colores a eleccion | D32: Tina 80X180 cm Myloa Norglas | J32: Tablero Embutido Electrico 36 Puestos | Q32: Puerta Interior Sinfonia 80 | S32: Masilla Base 25kg | X32: Posventa 40 pies | Y32: Ventana de PVC 100x 100 Termopanel corredera Linea bella
B33: Walking Closet 200 largo x 2,40 alto x 0,50 de profundidad | D33: Tina de baño Atenea 140x70x36 cm | J33: Tapas Ciegas Modulares Blancas | Q33: Puerta interior walking closet | S33: Melamina Blanco 15mm 183x250cm | X33: Posventa General | Y33: Ventana de PVC 100x 100 Termopanel corredera Winhouse
D34: Tinta adheviso con pasta AC 25kg | J34: Toma Exterior Tipo Legrand | Q34: Puerta Lenga Corsica 100x200 | S34: Membrana hidrofuga respirable 40m2 | X34: Posventa Uniones | Y34: Ventana Fija 0,70 x 0,60
D35: Urinario new campus blanco | J35: Tuberia emt 16mm x 3mts | Q35: Puerta Lenga Piamonte 100x200 | S35: Metalcon C 60X38X0,85X6Mts | X35: Viatico Entrega Proyecto (1p x dia) | Y35: Ventana Fija 100X 30
D36: Vanitorio Lavamanos Al Aire Vesanti 63 Centimentros | J36: Tubo Conduit 20Mm | Q36: Puerta livorno (Lenga)90 cm | S36: Monante Economico 38x60 0,5 x 240 | X36: Viatico estadia por personas | Y36: Ventana Fija 150x50
D37: Vinilit | J37: Vinilit Electrico | Q37: Puerta metaliza sinfonía | S37: Montante Normal 60X38X6X0,5Mm 2,4 Mts | X37: Viatico mueblista | Y37: Ventana Fija 200x100
D38: Wc One Pice | Q38: Puerta Pino Oregón Lanalhue 75x200 cm AFN | S38: OBS Estructural 11mm 122x244cm | X38: Viatico personas en terreno | Y38: Ventana Fija 50x100
Q39: Puerta pino solida canteria 85x2,00mt | S39: Osb Perimetral 9X1200X2440Mm | X39: Viatico Taller (4p x dia) | Y39: Ventana Fija 50x160
Q40: Puerta pvc termopanel con chapa 0,80x 2,00 | S40: Pasta De Muro | X40: Mano de Obra Adicional Juan Leon | Y40: Ventana Fija 70x160
...

Sheet BD Modelo
A1: Modelos | B1: Cantidad | C1: Costo Total | D1: Item | E1: Categorias | F1: Unidad | G1: P. Unitario real
A2: Baño 130x80 | B2: 4 | C2: =B2*G2 -> 18800 | D2: Angulo Aluminio 10x10 | E2: =VLOOKUP(D2,'BD Total'!$A$1:$G$506,2,0) -> Baño | F2: =VLOOKUP(D2,'BD Total'!$A$1:$G$506,3,0) -> Unidad | G2: =VLOOKUP(D2,'BD Total'!$A$1:$G$506,4,0) -> 4700
A3: Baño 130x80 | B3: 1 | C3: =B3*G3 -> 9000 | D3: Barra Pasamano Muro 50cm | E3: =VLOOKUP(D3,'BD Total'!$A$1:$G$506,2,0) -> Baño | F3: =VLOOKUP(D3,'BD Total'!$A$1:$G$506,3,0) -> Unidad | G3: =VLOOKUP(D3,'BD Total'!$A$1:$G$506,4,0) -> 9000
A4: Baño 130x80 | B4: 1 | C4: =B4*G4 -> 47000 | D4: Columna de Ducha Baño mono mando | E4: =VLOOKUP(D4,'BD Total'!$A$1:$G$506,2,0) -> Baño | F4: =VLOOKUP(D4,'BD Total'!$A$1:$G$506,3,0) -> Unidad | G4: =VLOOKUP(D4,'BD Total'!$A$1:$G$506,4,0) -> 47000
A5: Baño 130x80 | B5: 1 | C5: =B5*G5 -> 50000 | D5: Espejo Redondo Retroiluminado 60 Diametro | E5: =VLOOKUP(D5,'BD Total'!$A$1:$G$506,2,0) -> Baño | F5: =VLOOKUP(D5,'BD Total'!$A$1:$G$506,3,0) -> Unidad | G5: =VLOOKUP(D5,'BD Total'!$A$1:$G$506,4,0) -> 50000
A6: Baño 130x80 | B6: 1 | C6: =B6*G6 -> 15957.983 | D6: Extractor Aire baño 4" | E6: =VLOOKUP(D6,'BD Total'!$A$1:$G$506,2,0) -> Baño | F6: =VLOOKUP(D6,'BD Total'!$A$1:$G$506,3,0) -> Unidad | G6: =VLOOKUP(D6,'BD Total'!$A$1:$G$506,4,0) -> 15957.983
A7: Baño 130x80 | B7: 1 | C7: =B7*G7 -> 179048.82 | D7: Mampara ajustable 6mm 135 -150x185cm | E7: =VLOOKUP(D7,'BD Total'!$A$1:$G$506,2,0) -> Baño | F7: =VLOOKUP(D7,'BD Total'!$A$1:$G$506,3,0) -> Unidad | G7: =VLOOKUP(D7,'BD Total'!$A$1:$G$506,4,0) -> 179048.82
A8: Baño 130x80 | B8: 1 | C8: =B8*G8 -> 137000 | D8: Mueble Vanitorio 71 cm Fiumo Vessanti | E8: =VLOOKUP(D8,'BD Total'!$A$1:$G$506,2,0) -> Baño | F8: =VLOOKUP(D8,'BD Total'!$A$1:$G$506,3,0) -> Unidad | G8: =VLOOKUP(D8,'BD Total'!$A$1:$G$506,4,0) -> 137000
A9: Baño 130x80 | B9: 1 | C9: =B9*G9 -> 159000 | D9: Receptáculo 130x80 | E9: =VLOOKUP(D9,'BD Total'!$A$1:$G$506,2,0) -> Baño | F9: =VLOOKUP(D9,'BD Total'!$A$1:$G$506,3,0) -> Unidad | G9: =VLOOKUP(D9,'BD Total'!$A$1:$G$506,4,0) -> 159000
A10: Baño 130x80 | B10: 1 | C10: =B10*G10 -> 160000 | D10: Wc One Pice | E10: =VLOOKUP(D10,'BD Total'!$A$1:$G$506,2,0) -> Baño | F10: =VLOOKUP(D10,'BD Total'!$A$1:$G$506,3,0) -> Unidad | G10: =VLOOKUP(D10,'BD Total'!$A$1:$G$506,4,0) -> 160000
A11: Baño 130x80 | B11: 1 | C11: =B11*G11 -> 15000 | D11: Llaves Monomando - Lava Manos | E11: =VLOOKUP(D11,'BD Total'!$A$1:$G$506,2,0) -> Grifería | F11: =VLOOKUP(D11,'BD Total'!$A$1:$G$506,3,0) -> Unidad | G11: =VLOOKUP(D11,'BD Total'!$A$1:$G$506,4,0) -> 15000
A12: Baño 130x80 | B12: 2 | C12: =B12*G12 -> 3680.6723 | D12: Fragüe cerámico 1 kg | E12: =VLOOKUP(D12,'BD Total'!$A$1:$G$506,2,0) -> Baño | F12: =VLOOKUP(D12,'BD Total'!$A$1:$G$506,3,0) -> Unidad | G12: =VLOOKUP(D12,'BD Total'!$A$1:$G$506,4,0) -> 1840.3361
A13: Baño 130x80 | B13: 9 | C13: =B13*G13 -> 75554.622 | D13: Porcelanato color Haya WF61515 15x60 cm | E13: =VLOOKUP(D13,'BD Total'!$A$1:$G$506,2,0) -> Baño | F13: =VLOOKUP(D13,'BD Total'!$A$1:$G$506,3,0) -> m2 | G13: =VLOOKUP(D13,'BD Total'!$A$1:$G$506,4,0) -> 8394.958
... A44: Electricidad 30 m2 | B44: 100 | C44: =B44*G44 -> 11200 | D44: Abrazaderas Metalicas | E44: =VLOOKUP(D44,'BD Total'!$A$1:$G$506,2,0) -> Electricidad | F44: =VLOOKUP(D44,'BD Total'!$A$1:$G$506,3,0) -> Unidad | G44: =VLOOKUP(D44,'BD Total'!$A$1:$G$506,4,0) -> 112
A45: Electricidad 30 m2 | B45: 1 | C45: =B45*G45 -> 3500 | D45: Automatico 16 Amperes | E45: =VLOOKUP(D45,'BD Total'!$A$1:$G$506,2,0) -> Electricidad | F45: =VLOOKUP(D45,'BD Total'!$A$1:$G$506,3,0) -> Unidad | G45: =VLOOKUP(D45,'BD Total'!$A$1:$G$506,4,0) -> 3500 | H45: circuito iluminacion
A46: Electricidad 30 m2 | B46: 3 | C46: =B46*G46 -> 10500 | D46: Automatico 25 Amperes | E46: =VLOOKUP(D46,'BD Total'!$A$1:$G$506,2,0) -> Electricidad | F46: =VLOOKUP(D46,'BD Total'!$A$1:$G$506,3,0) -> Unidad | G46: =VLOOKUP(D46,'BD Total'!$A$1:$G$506,4,0) -> 3500 | H46: aire. Cocina y enchufe
A47: Electricidad 30 m2 | B47: 1 | C47: =B47*G47 -> 9900 | D47: Bipolar | E47: =VLOOKUP(D47,'BD Total'!$A$1:$G$506,2,0) -> Electricidad | F47: =VLOOKUP(D47,'BD Total'!$A$1:$G$506,3,0) -> Unidad | G47: =VLOOKUP(D47,'BD Total'!$A$1:$G$506,4,0) -> 9900
A48: Electricidad 30 m2 | B48: 3 | C48: =B48*G48 -> 39315 | D48: Cableado 1,5 En Eva - Rollo 50m | E48: =VLOOKUP(D48,'BD Total'!$A$1:$G$506,2,0) -> Electricidad | F48: =VLOOKUP(D48,'BD Total'!$A$1:$G$506,3,0) -> Unidad | G48: =VLOOKUP(D48,'BD Total'!$A$1:$G$506,4,0) -> 13105
A49: Electricidad 30 m2 | B49: 3 | C49: =B49*G49 -> 52500 | D49: Cableado 2,5 En Eva - Rollo 50m | E49: =VLOOKUP(D49,'BD Total'!$A$1:$G$506,2,0) -> Electricidad | F49: =VLOOKUP(D49,'BD Total'!$A$1:$G$506,3,0) -> Unidad | G49: =VLOOKUP(D49,'BD Total'!$A$1:$G$506,4,0) -> 17500
A50: Electricidad 30 m2 | B50: 2 | C50: =B50*G50 -> 4521.0084 | D50: Caja 100 x 65 x 100 mm Estanca Blanco Mec | E50: =VLOOKUP(D50,'BD Total'!$A$1:$G$506,2,0) -> Electricidad | F50: =VLOOKUP(D50,'BD Total'!$A$1:$G$506,3,0) -> Unidad | G50: =VLOOKUP(D50,'BD Total'!$A$1:$G$506,4,0) -> 2260.5042
A51: Electricidad 30 m2 | B51: 35 | C51: =B51*G51 -> 28000 | D51: Caja De Distribución | E51: =VLOOKUP(D51,'BD Total'!$A$1:$G$506,2,0) -> Electricidad | F51: =VLOOKUP(D51,'BD Total'!$A$1:$G$506,3,0) -> Unidad | G51: =VLOOKUP(D51,'BD Total'!$A$1:$G$506,4,0) -> 800
A52: Electricidad 30 m2 | B52: 2 | C52: =B52*G52 -> 3000 | D52: Caja estanca exterior | E52: =VLOOKUP(D52,'BD Total'!$A$1:$G$506,2,0) -> Electricidad | F52: =VLOOKUP(D52,'BD Total'!$A$1:$G$506,3,0) -> Unidad | G52: =VLOOKUP(D52,'BD Total'!$A$1:$G$506,4,0) -> 1500
A53: Electricidad 30 m2 | B53: 1 | C53: =B53*G53 -> 1200 | D53: Cinta Aislante | E53: =VLOOKUP(D53,'BD Total'!$A$1:$G$506,2,0) -> Electricidad | F53: =VLOOKUP(D53,'BD Total'!$A$1:$G$506,3,0) -> Unidad | G53: =VLOOKUP(D53,'BD Total'!$A$1:$G$506,4,0) -> 1200
A54: Electricidad 30 m2 | B54: 1 | C54: =B54*G54 -> 5600 | D54: Conectores Conicos 1,5 | E54: =VLOOKUP(D54,'BD Total'!$A$1:$G$506,2,0) -> Electricidad | F54: =VLOOKUP(D54,'BD Total'!$A$1:$G$506,3,0) -> Paquete | G54: =VLOOKUP(D54,'BD Total'!$A$1:$G$506,4,0) -> 5600
A55: Electricidad 30 m2 | B55: 1 | C55: =B55*G55 -> 5600 | D55: Conectores Conicos 2,5 | E55: =VLOOKUP(D55,'BD Total'!$A$1:$G$506,2,0) -> Electricidad | F55: =VLOOKUP(D55,'BD Total'!$A$1:$G$506,3,0) -> Paquete | G55: =VLOOKUP(D55,'BD Total'!$A$1:$G$506,4,0) -> 5600
A56: Electricidad 30 m2 | B56: 90 | C56: =B56*G56 -> 33300 | D56: Conectores Terminales 20Mm | E56: =VLOOKUP(D56,'BD Total'!$A$1:$G$506,2,0) -> Electricidad | F56: =VLOOKUP(D56,'BD Total'!$A$1:$G$506,3,0) -> Paquete | G56: =VLOOKUP(D56,'BD Total'!$A$1:$G$506,4,0) -> 370
A57: Electricidad 30 m2 | B57: 4 | C57: =B57*G57 -> 8000 | D57: Diferenciales De 25 O 32 Amperes | E57: =VLOOKUP(D57,'BD Total'!$A$1:$G$506,2,0) -> Electricidad | F57: =VLOOKUP(D57,'BD Total'!$A$1:$G$506,3,0) -> Unidad | G57: =VLOOKUP(D57,'BD Total'!$A$1:$G$506,4,0) -> 2000
A58: Electricidad 30 m2 | B58: 2 | C58: =B58*G58 -> 4920 | D58: Enchufe Simple 16 ap | E58: =VLOOKUP(D58,'BD Total'!$A$1:$G$506,2,0) -> Electricidad | F58: =VLOOKUP(D58,'BD Total'!$A$1:$G$506,3,0) -> Unidad | G58: =VLOOKUP(D58,'BD Total'!$A$1:$G$506,4,0) -> 2460
A59: Electricidad 30 m2 | B59: 14 | C59: =B59*G59 -> 42000 | D59: Enchufes Dobles | E59: =VLOOKUP(D59,'BD Total'!$A$1:$G$506,2,0) -> Electricidad | F59: =VLOOKUP(D59,'BD Total'!$A$1:$G$506,3,0) -> Unidad | G59: =VLOOKUP(D59,'BD Total'!$A$1:$G$506,4,0) -> 3000 | H59: considera 3 enchufes dobles - 1 de 16ap - (habitacion)
A60: Electricidad 30 m2 | B60: 1 | C60: =B60*G60 -> 11000 | D60: Enchufes Dobles Ip65 | E60: =VLOOKUP(D60,'BD Total'!$A$1:$G$506,2,0) -> Electricidad | F60: =VLOOKUP(D60,'BD Total'!$A$1:$G$506,3,0) -> Unidad | G60: =VLOOKUP(D60,'BD Total'!$A$1:$G$506,4,0) -> 11000
A61: Electricidad 30 m2 | B61: 1 | C61: =B61*G61 -> 1300 | D61: Fruler 1,5 | E61: =VLOOKUP(D61,'BD Total'!$A$1:$G$506,2,0) -> Electricidad | F61: =VLOOKUP(D61,'BD Total'!$A$1:$G$506,3,0) -> Paquete | G61: =VLOOKUP(D61,'BD Total'!$A$1:$G$506,4,0) -> 1300
A62: Electricidad 30 m2 | B62: 1 | C62: =B62*G62 -> 1300 | D62: Fruler 2,5 | E62: =VLOOKUP(D62,'BD Total'!$A$1:$G$506,2,0) -> Electricidad | F62: =VLOOKUP(D62,'BD Total'!$A$1:$G$506,3,0) -> Paquete | G62: =VLOOKUP(D62,'BD Total'!$A$1:$G$506,4,0) -> 1300
A63: Electricidad 30 m2 | B63: 1 | C63: =B63*G63 -> 5000 | D63: Fusible 25 Amperes | E63: =VLOOKUP(D63,'BD Total'!$A$1:$G$506,2,0) -> Electricidad | F63: =VLOOKUP(D63,'BD Total'!$A$1:$G$506,3,0) -> Unidad | G63: =VLOOKUP(D63,'BD Total'!$A$1:$G$506,4,0) -> 5000
A64: Electricidad 30 m2 | B64: 1 | C64: =B64*G64 -> 6000 | D64: Interruptor 915 | E64: =VLOOKUP(D64,'BD Total'!$A$1:$G$506,2,0) -> Electricidad | F64: =VLOOKUP(D64,'BD Total'!$A$1:$G$506,3,0) -> Unidad | G64: =VLOOKUP(D64,'BD Total'!$A$1:$G$506,4,0) -> 6000
A65: Electricidad 30 m2 | B65: 1 | C65: =B65*G65 -> 2000 | D65: Interruptores 912 | E65: =VLOOKUP(D65,'BD Total'!$A$1:$G$506,2,0) -> Electricidad | F65: =VLOOKUP(D65,'BD Total'!$A$1:$G$506,3,0) -> Unidad | G65: =VLOOKUP(D65,'BD Total'!$A$1:$G$506,4,0) -> 2000
A66: Electricidad 30 m2 | B66: 1 | C66: =B66*G66 -> 10084 | D66: Regleta Para Tablero | E66: =VLOOKUP(D66,'BD Total'!$A$1:$G$506,2,0) -> Electricidad | F66: =VLOOKUP(D66,'BD Total'!$A$1:$G$506,3,0) -> Unidad | G66: =VLOOKUP(D66,'BD Total'!$A$1:$G$506,4,0) -> 10084
A67: Electricidad 30 m2 | B67: 1 | C67: =B67*G67 -> 13500 | D67: Tablero Embutido Electrico 24 Puestos | E67: =VLOOKUP(D67,'BD Total'!$A$1:$G$506,2,0) -> Electricidad | F67: =VLOOKUP(D67,'BD Total'!$A$1:$G$506,3,0) -> Unidad | G67: =VLOOKUP(D67,'BD Total'!$A$1:$G$506,4,0) -> 13500
A68: Electricidad 30 m2 | B68: 5 | C68: =B68*G68 -> 10000 | D68: Tapas Ciegas Modulares Blancas | E68: =VLOOKUP(D68,'BD Total'!$A$1:$G$506,2,0) -> Electricidad | F68: =VLOOKUP(D68,'BD Total'!$A$1:$G$506,3,0) -> Unidad | G68: =VLOOKUP(D68,'BD Total'!$A$1:$G$506,4,0) -> 2000
A69: Electricidad 30 m2 | B69: 40 | C69: =B69*G69 -> 27200 | D69: Tubo Conduit 20Mm | E69: =VLOOKUP(D69,'BD Total'!$A$1:$G$506,2,0) -> Electricidad | F69: =VLOOKUP(D69,'BD Total'!$A$1:$G$506,3,0) -> Unidad | G69: =VLOOKUP(D69,'BD Total'!$A$1:$G$506,4,0) -> 680
A70: Electricidad 30 m2 | B70: 7 | C70: =B70*G70 -> 64647.059 | D70: Iluminación Exterior | E70: =VLOOKUP(D70,'BD Total'!$A$1:$G$506,2,0) -> Iluminación | F70: =VLOOKUP(D70,'BD Total'!$A$1:$G$506,3,0) -> Unidad | G70: =VLOOKUP(D70,'BD Total'!$A$1:$G$506,4,0) -> 9235.2941
...

Sheet Cubicador
B2: Volcanitas Cielo | E2: Volcanitas Lisa (AZULES) | H2: Volcanitas RH (VERDE) | K2: Poliuretano | N2: OSB
C3: 1 | F3: 1 | I3: 1
C4: 1 | F4: 1 | I4: 1 | K4: Largo | L4: 55 | N4: Volcanita Lisa | O4: =F55 -> 0.0041666667
C5: 1 | F5: 1 | I5: 1 | K5: Alto | L5: 2 | N5: Volcanita RH | O5: =I55 -> 10.189167
C6: 1 | F6: 1 | I6: 1 | K6: Total Paredes | L6: =L4*L5*2 -> 220 | N6: Total Volcanitas | O6: =SUM(O4:O5) -> 10.193333
C7: 1 | F7: 1 | I7: 12222
I8: 1 | K8: Ancho | L8: 77 | N8: Nota Referencia cielo
K9: Alto | L9: 12 | N9: Volcanita Cielo Contendor 20 Pies | P9: 5
K10: Total Puertas | L10: =L8*L9*2 -> 1848 | N10: Volcanita Cielo Contendor 40 Pies | P10: 10
K12: Largo | L12: 12
K13: Ancho | L13: 12
K14: Total Techo | L14: =L12*L13 -> 144
K16: Total Poliuretano | L16: =L14+L10+L6 -> 2212
B55: Total Volcanita Lisa | C55: =SUM(C3:C54)/1200 -> 0.0041666667 | E55: Total Volcanita Lisa | F55: =SUM(F3:F54)/1200 -> 0.0041666667 | H55: Total Volcanita Lisa | I55: =SUM(I3:I54)/1200 -> 10.189167

Sheet Categorias Varios
A1: Varios | B1: Uso | D1: 13 | E1: Siempre
A2: Arriendo Taller De Construcción | B2: Siempre
A3: Baño Quimico | B3: Si es en Región
A4: Bono Cumplimiento meta | B4: Siempre
A5: Camioneta Alan Bencina Tag Y Mantencion | B5: Siempre
A6: Camioneta Miguel trabajo en terreno | B6: Si es en Región
A7: Conexión de Gas y Encimera | B7: Siempre
A8: Corte y soldadura de contenedor | B8: Depende
A9: Cortes de contenedor 20 pies | B9: Depende
A10: Electricidad Maestranza 20 pies | B10: Depende
A11: Electricidad Maestranza 40 pies | B11: Depende
A12: Firma contrato | B12: Siempre
A13: Flete Contenedor | B13: Siempre
... A40: Mano de Obra Adicional Juan Leon | B40: Depende

Sheet 1 - Modelo
D5: Recuadro de Valores Proyecto
D7: Total Proyecto | F7: =SUM(F12:F1048576) -> 1243805
A9: Categorias | B9: Item | C9: Unidad | D9: Cantidad | E9: P. Unitario | F9: P. Total
A12: Tabiquería | B12: Canal Cielo 20X 25 0,4mm x 3m | C12: Unidad | D12: 8 | E12: 1000 | F12: 8000
B13: Cielo Portante 40X18X10X0,5Mm 3Mts | C13: Unidad | D13: 32 | E13: 1263 | F13: 40416
B14: Cinta malla para yeso | C14: Unidad | D14: 1 | E14: 3300 | F14: 3300
B15: Cornisas | C15: Unidad | D15: 20 | E15: 1200 | F15: 24000
B16: Esquinero metalcom 30x30x 0,4mm 240 | C16: Unidad | D16: 1 | E16: 1100 | F16: 1100
B17: Guardapolvos | C17: Unidad | D17: 20 | E17: 2765 | F17: 55300
B18: Masilla Base 25kg | C18: Unidad | D18: 1 | E18: 19400 | F18: 19400
B19: Osb Perimetral 9X1200X2440Mm | C19: Unidad | D19: 47 | E19: 8951 | F19: 420697
B20: Pasta De Muro | C20: Tineta | D20: 1 | E20: 18000 | F20: 18000
B21: Perfil 30 x 30 2mm 6 metros | C21: Unidad | D21: 8 | E21: 11000 | F21: 88000
B22: Rollo Mig de 15kilo | C22: General | D22: 1 | E22: 10500 | F22: 10500
B23: Sello Poliuretano Pate | C23: Unidad | D23: 2 | E23: 5450 | F23: 10900
B24: Silicona Acrilica | C24: Unidad | D24: 6 | E24: 2690 | F24: 16140
... B30: Vulcometal Estructura Muros 60 X 38 0,85 6 Mts | C30: Unidad | D30: 30 | E30: 6222 | F30: 186660

Sheet 2 - Traspasar Modelo
A5: Primero: Seleccionar en "1 - Modelo" lo que vamos a traspasar.
A6: Segundo: en la hoja "2 - Traspasar Modelo" en donde aparecen automatico lo que vamos a traspasar, Copiar juntos (Categorias e Item) y luego Copiar (Cantidades) a hoja "1 - Cotizador Personalizado".
A9: 1 - Seleccionar "Categorias y Item" Juntos | C9: 2 - Seleccionar y copiar cantidades
A11: Categorias | B11: Item | C11: Cantidad
A12: =IFERROR(VLOOKUP(B12,'BD Total'!$A$1:$B$506,2,0),"") -> Tabiquería | B12: ='1 - Modelo'!B12 -> Canal Cielo 20X 25 0,4mm x 3m | C12: ='1 - Modelo'!D12 -> 8
A13: =IFERROR(VLOOKUP(B13,'BD Total'!$A$1:$B$506,2,0),"") -> Tabiquería | B13: ='1 - Modelo'!B13 -> Cielo Portante 40X18X10X0,5Mm 3Mts | C13: ='1 - Modelo'!D13 -> 32
A14: =IFERROR(VLOOKUP(B14,'BD Total'!$A$1:$B$506,2,0),"") -> Tabiquería | B14: ='1 - Modelo'!B14 -> Cinta malla para yeso | C14: ='1 - Modelo'!D14 -> 1
A15: =IFERROR(VLOOKUP(B15,'BD Total'!$A$1:$B$506,2,0),"") -> Tabiquería | B15: ='1 - Modelo'!B15 -> Cornisas | C15: ='1 - Modelo'!D15 -> 20
A16: =IFERROR(VLOOKUP(B16,'BD Total'!$A$1:$B$506,2,0),"") -> Tabiquería | B16: ='1 - Modelo'!B16 -> Esquinero metalcom 30x30x 0,4mm 240 | C16: ='1 - Modelo'!D16 -> 1
A17: =IFERROR(VLOOKUP(B17,'BD Total'!$A$1:$B$506,2,0),"") -> Tabiquería | B17: ='1 - Modelo'!B17 -> Guardapolvos | C17: ='1 - Modelo'!D17 -> 20
A18: =IFERROR(VLOOKUP(B18,'BD Total'!$A$1:$B$506,2,0),"") -> Tabiquería | B18: ='1 - Modelo'!B18 -> Masilla Base 25kg | C18: ='1 - Modelo'!D18 -> 1
A19: =IFERROR(VLOOKUP(B19,'BD Total'!$A$1:$B$506,2,0),"") -> Tabiquería | B19: ='1 - Modelo'!B19 -> Osb Perimetral 9X1200X2440Mm | C19: ='1 - Modelo'!D19 -> 47
A20: =IFERROR(VLOOKUP(B20,'BD Total'!$A$1:$B$506,2,0),"") -> Tabiquería | B20: ='1 - Modelo'!B20 -> Pasta De Muro | C20: ='1 - Modelo'!D20 -> 1
A21: =IFERROR(VLOOKUP(B21,'BD Total'!$A$1:$B$506,2,0),"") -> Tabiquería | B21: ='1 - Modelo'!B21 -> Perfil 30 x 30 2mm 6 metros | C21: ='1 - Modelo'!D21 -> 8
A22: =IFERROR(VLOOKUP(B22,'BD Total'!$A$1:$B$506,2,0),"") -> Tabiquería | B22: ='1 - Modelo'!B22 -> Rollo Mig de 15kilo | C22: ='1 - Modelo'!D22 -> 1
A23: =IFERROR(VLOOKUP(B23,'BD Total'!$A$1:$B$506,2,0),"") -> Tabiquería | B23: ='1 - Modelo'!B23 -> Sello Poliuretano Pate | C23: ='1 - Modelo'!D23 -> 2
... A155: =IFERROR(VLOOKUP(B155,'BD Total'!$A$1:$B$506,2,0),"") | B155: ='1 - Modelo'!B155 -> 0 | C155: ='1 - Modelo'!D155 -> 0

Sheet 1 - Cotizador Personalizado
E2: Recuadro de Valores Proyecto
E4: Costos Totales | G4: =SUM(G14:G1048576) -> 39331406
B6: Buscador | C6: Ventana Corredera 1,50 X 1,50 Termopanel Pvc Bl/Fol Madera/ Negro | E6: Sub - Totales | G6: ='2 - Margenes Proyecto'!G7 -> 51917456
B7: ¿Donde esta? | C7: =IFERROR(VLOOKUP(C6,'BD Total'!A1:E506,2,0),"") -> Ventana | E7: IVA | G7: ='2 - Margenes Proyecto'!C10 -> 9864316.6
B8: Valor | C8: =IFERROR(VLOOKUP(C6,'BD Total'!A1:E507,4,0),"") -> 362000 | E8: Total Proyecto | G8: =SUM(G6:G7) -> 61781772
B13: Categorias | C13: Item | D13: Unidad | E13: Cantidad | F13: P. Unitario | G13: P. Total | H13: Hoja Impresión Clte. | I13: Hoja Impresión Compras.
B14: Adicionales | C14: Conexión de Lavadora | D14: =IFERROR(VLOOKUP(C14,'BD Total'!$A$1:$H$506,3,0),"") -> Unidad | E14: 1 | F14: =IFERROR(VLOOKUP(C14,'BD Total'!$A$1:$H$506,4,0),"") -> 50000 | G14: =IFERROR(F14*E14,"") -> 50000 | H14: =IFERROR(VLOOKUP(C14,'BD Total'!$A$1:$G$506,6,0),"") -> Si | I14: =IFERROR(VLOOKUP(C14,'BD Total'!$A$1:$G$506,7,0),"") -> Si
B15: Adicionales | C15: Closet de Tres cuerpos - Piso a techo | D15: =IFERROR(VLOOKUP(C15,'BD Total'!$A$1:$H$506,3,0),"") -> Unidad | E15: 2 | F15: =IFERROR(VLOOKUP(C15,'BD Total'!$A$1:$H$506,4,0),"") -> 350000 | G15: =IFERROR(F15*E15,"") -> 700000 | H15: =IFERROR(VLOOKUP(C15,'BD Total'!$A$1:$G$506,6,0),"") -> Si | I15: =IFERROR(VLOOKUP(C15,'BD Total'!$A$1:$G$506,7,0),"") -> Si
B16: Adicionales | C16: Walking Closet 200 largo x 2,40 alto x 0,50 de profundidad | D16: =IFERROR(VLOOKUP(C16,'BD Total'!$A$1:$H$506,3,0),"") -> Unidad | E16: 1 | F16: =IFERROR(VLOOKUP(C16,'BD Total'!$A$1:$H$506,4,0),"") -> 540000 | G16: =IFERROR(F16*E16,"") -> 540000 | H16: =IFERROR(VLOOKUP(C16,'BD Total'!$A$1:$G$506,6,0),"") -> Si | I16: =IFERROR(VLOOKUP(C16,'BD Total'!$A$1:$G$506,7,0),"") -> Si
B17: Adicionales | C17: Gabinete para Calefont 11 litros | D17: =IFERROR(VLOOKUP(C17,'BD Total'!$A$1:$H$506,3,0),"") -> Unidad | E17: 1 | F17: =IFERROR(VLOOKUP(C17,'BD Total'!$A$1:$H$506,4,0),"") -> 70400 | G17: =IFERROR(F17*E17,"") -> 70400 | H17: =IFERROR(VLOOKUP(C17,'BD Total'!$A$1:$G$506,6,0),"") -> Si | I17: =IFERROR(VLOOKUP(C17,'BD Total'!$A$1:$G$506,7,0),"") -> Si
B18: Baño | C18: Tinta adheviso con pasta AC 25kg | D18: =IFERROR(VLOOKUP(C18,'BD Total'!$A$1:$H$506,3,0),"") -> Unidad | E18: 8 | F18: =IFERROR(VLOOKUP(C18,'BD Total'!$A$1:$H$506,4,0),"") -> 17638.655 | G18: =IFERROR(F18*E18,"") -> 141109.24 | H18: =IFERROR(VLOOKUP(C18,'BD Total'!$A$1:$G$506,6,0),"") -> No | I18: =IFERROR(VLOOKUP(C18,'BD Total'!$A$1:$G$506,7,0),"") -> Si
B19: Aislación | C19: Poliuretano Proyectado | D19: =IFERROR(VLOOKUP(C19,'BD Total'!$A$1:$H$506,3,0),"") -> m2 | E19: 190 | F19: =IFERROR(VLOOKUP(C19,'BD Total'!$A$1:$H$506,4,0),"") -> 8000 | G19: =IFERROR(F19*E19,"") -> 1520000 | H19: =IFERROR(VLOOKUP(C19,'BD Total'!$A$1:$G$506,6,0),"") -> Si | I19: =IFERROR(VLOOKUP(C19,'BD Total'!$A$1:$G$506,7,0),"") -> Si
B20: Baño | C20: Desagues Ducha | D20: =IFERROR(VLOOKUP(C20,'BD Total'!$A$1:$H$506,3,0),"") -> Unidad | E20: 3 | F20: =IFERROR(VLOOKUP(C20,'BD Total'!$A$1:$H$506,4,0),"") -> 5000 | G20: =IFERROR(F20*E20,"") -> 15000 | H20: =IFERROR(VLOOKUP(C20,'BD Total'!$A$1:$G$506,6,0),"") -> No | I20: =IFERROR(VLOOKUP(C20,'BD Total'!$A$1:$G$506,7,0),"") -> Si
B21: Baño | C21: Desgues Lavamos | D21: =IFERROR(VLOOKUP(C21,'BD Total'!$A$1:$H$506,3,0),"") -> Unidad | E21: 3 | F21: =IFERROR(VLOOKUP(C21,'BD Total'!$A$1:$H$506,4,0),"") -> 3500 | G21: =IFERROR(F21*E21,"") -> 10500 | H21: =IFERROR(VLOOKUP(C21,'BD Total'!$A$1:$G$506,6,0),"") -> No | I21: =IFERROR(VLOOKUP(C21,'BD Total'!$A$1:$G$506,7,0),"") -> Si
B22: Baño | C22: Kit Instalacion Sanitario Wc | D22: =IFERROR(VLOOKUP(C22,'BD Total'!$A$1:$H$506,3,0),"") -> Unidad | E22: 3 | F22: =IFERROR(VLOOKUP(C22,'BD Total'!$A$1:$H$506,4,0),"") -> 10084 | G22: =IFERROR(F22*E22,"") -> 30252 | H22: =IFERROR(VLOOKUP(C22,'BD Total'!$A$1:$G$506,6,0),"") -> No | I22: =IFERROR(VLOOKUP(C22,'BD Total'!$A$1:$G$506,7,0),"") -> Si
B23: Baño | C23: Porcelanato Blanco Brillante 60x60cm | D23: =IFERROR(VLOOKUP(C23,'BD Total'!$A$1:$H$506,3,0),"") -> m2 | E23: 27 | F23: =IFERROR(VLOOKUP(C23,'BD Total'!$A$1:$H$506,4,0),"") -> 6992 | G23: =IFERROR(F23*E23,"") -> 188784 | H23: =IFERROR(VLOOKUP(C23,'BD Total'!$A$1:$G$506,6,0),"") -> Si | I23: =IFERROR(VLOOKUP(C23,'BD Total'!$A$1:$G$506,7,0),"") -> Si
B24: Baño | C24: Receptáculo 130x80 | D24: =IFERROR(VLOOKUP(C24,'BD Total'!$A$1:$H$506,3,0),"") -> Unidad | E24: 3 | F24: =IFERROR(VLOOKUP(C24,'BD Total'!$A$1:$H$506,4,0),"") -> 159000 | G24: =IFERROR(F24*E24,"") -> 477000 | H24: =IFERROR(VLOOKUP(C24,'BD Total'!$A$1:$G$506,6,0),"") -> Si | I24: =IFERROR(VLOOKUP(C24,'BD Total'!$A$1:$G$506,7,0),"") -> Si
B25: Baño | C25: Volcanita Rh 12,5 | D25: =IFERROR(VLOOKUP(C25,'BD Total'!$A$1:$H$506,3,0),"") -> Unidad | E25: 21 | F25: =IFERROR(VLOOKUP(C25,'BD Total'!$A$1:$H$506,4,0),"") -> 11336 | G25: =IFERROR(F25*E25,"") -> 238056 | H25: =IFERROR(VLOOKUP(C25,'BD Total'!$A$1:$G$506,6,0),"") -> Si | I25: =IFERROR(VLOOKUP(C25,'BD Total'!$A$1:$G$506,7,0),"") -> Si
... B31: Baño | C31: Teflon | D31: =IFERROR(VLOOKUP(C31,'BD Total'!$A$1:$H$506,3,0),"") -> Unidad | E31: 3 | F31: =IFERROR(VLOOKUP(C31,'BD Total'!$A$1:$H$506,4,0),"") -> 1500 | G31: =IFERROR(F31*E31,"") -> 4500 | H31: =IFERROR(VLOOKUP(C31,'BD Total'!$A$1:$G$506,6,0),"") -> No | I31: =IFERROR(VLOOKUP(C31,'BD Total'!$A$1:$G$506,7,0),"") -> Si
B32: Adicionales | C32: Closet de Tres cuerpos - Piso a techo | D32: =IFERROR(VLOOKUP(C32,'BD Total'!$A$1:$H$506,3,0),"") -> Unidad | E32: 1 | F32: =IFERROR(VLOOKUP(C32,'BD Total'!$A$1:$H$506,4,0),"") -> 350000 | G32: =IFERROR(F32*E32,"") -> 350000 | H32: =IFERROR(VLOOKUP(C32,'BD Total'!$A$1:$G$506,6,0),"") -> Si | I32: =IFERROR(VLOOKUP(C32,'BD Total'!$A$1:$G$506,7,0),"") -> Si | J32: adicional x valor
B33: Sanitario | C33: Desagues Lavaplatos | D33: =IFERROR(VLOOKUP(C33,'BD Total'!$A$1:$H$506,3,0),"") -> Unidad | E33: 1 | F33: =IFERROR(VLOOKUP(C33,'BD Total'!$A$1:$H$506,4,0),"") -> 5000 | G33: =IFERROR(F33*E33,"") -> 5000 | H33: =IFERROR(VLOOKUP(C33,'BD Total'!$A$1:$G$506,6,0),"") -> No | I33: =IFERROR(VLOOKUP(C33,'BD Total'!$A$1:$G$506,7,0),"") -> Si
B34: Baño | C34: Mampara ajustable 6mm 135 -150x185cm | D34: =IFERROR(VLOOKUP(C34,'BD Total'!$A$1:$H$506,3,0),"") -> Unidad | E34: 3 | F34: =IFERROR(VLOOKUP(C34,'BD Total'!$A$1:$H$506,4,0),"") -> 179048.82 | G34: =IFERROR(F34*E34,"") -> 537146.47 | H34: =IFERROR(VLOOKUP(C34,'BD Total'!$A$1:$G$506,6,0),"") -> Si | I34: =IFERROR(VLOOKUP(C34,'BD Total'!$A$1:$G$506,7,0),"") -> Si
B35: Cocina | C35: Lavaplatos Embutido | D35: =IFERROR(VLOOKUP(C35,'BD Total'!$A$1:$H$506,3,0),"") -> Unidad | E35: 1 | F35: =IFERROR(VLOOKUP(C35,'BD Total'!$A$1:$H$506,4,0),"") -> 82345 | G35: =IFERROR(F35*E35,"") -> 82345 | H35: =IFERROR(VLOOKUP(C35,'BD Total'!$A$1:$G$506,6,0),"") -> Si | I35: =IFERROR(VLOOKUP(C35,'BD Total'!$A$1:$G$506,7,0),"") -> Si
B36: Cocina | C36: Mueble de cocina Cub Cuarzo 3,20 mts + Aereo+Encimera+horno+Campana+ Isla Cuarzo | D36: =IFERROR(VLOOKUP(C36,'BD Total'!$A$1:$H$506,3,0),"") -> Unidad | E36: 1 | F36: =IFERROR(VLOOKUP(C36,'BD Total'!$A$1:$H$506,4,0),"") -> 2070000 | G36: =IFERROR(F36*E36,"") -> 2070000 | H36: =IFERROR(VLOOKUP(C36,'BD Total'!$A$1:$G$506,6,0),"") -> Si | I36: =IFERROR(VLOOKUP(C36,'BD Total'!$A$1:$G$506,7,0),"") -> Si
B37: Cocina | C37: Llave gas encimera | D37: =IFERROR(VLOOKUP(C37,'BD Total'!$A$1:$H$506,3,0),"") -> Unidad | E37: 1 | F37: =IFERROR(VLOOKUP(C37,'BD Total'!$A$1:$H$506,4,0),"") -> 22500 | G37: =IFERROR(F37*E37,"") -> 22500 | H37: =IFERROR(VLOOKUP(C37,'BD Total'!$A$1:$G$506,6,0),"") -> No | I37: =IFERROR(VLOOKUP(C37,'BD Total'!$A$1:$G$506,7,0),"") -> Si
B38: Container | C38: Container Maritimo HC 12 x 2,44 x 2,89 - 40 Pies | D38: =IFERROR(VLOOKUP(C38,'BD Total'!$A$1:$H$506,3,0),"") -> Unidad | E38: 3 | F38: =IFERROR(VLOOKUP(C38,'BD Total'!$A$1:$H$506,4,0),"") -> 1950000 | G38: =IFERROR(F38*E38,"") -> 5850000 | H38: =IFERROR(VLOOKUP(C38,'BD Total'!$A$1:$G$506,6,0),"") -> Si | I38: =IFERROR(VLOOKUP(C38,'BD Total'!$A$1:$G$506,7,0),"") -> No
B39: Electricidad | C39: Automatico 16 Amperes | D39: =IFERROR(VLOOKUP(C39,'BD Total'!$A$1:$H$506,3,0),"") -> Unidad | E39: 1 | F39: =IFERROR(VLOOKUP(C39,'BD Total'!$A$1:$H$506,4,0),"") -> 3500 | G39: =IFERROR(F39*E39,"") -> 3500 | H39: =IFERROR(VLOOKUP(C39,'BD Total'!$A$1:$G$506,6,0),"") -> No | I39: =IFERROR(VLOOKUP(C39,'BD Total'!$A$1:$G$506,7,0),"") -> Si
B40: Electricidad | C40: Automatico 25 Amperes | D40: =IFERROR(VLOOKUP(C40,'BD Total'!$A$1:$H$506,3,0),"") -> Unidad | E40: 3 | F40: =IFERROR(VLOOKUP(C40,'BD Total'!$A$1:$H$506,4,0),"") -> 3500 | G40: =IFERROR(F40*E40,"") -> 10500 | H40: =IFERROR(VLOOKUP(C40,'BD Total'!$A$1:$G$506,6,0),"") -> No | I40: =IFERROR(VLOOKUP(C40,'BD Total'!$A$1:$G$506,7,0),"") -> Si
B41: Electricidad | C41: Bipolar | D41: =IFERROR(VLOOKUP(C41,'BD Total'!$A$1:$H$506,3,0),"") -> Unidad | E41: 1 | F41: =IFERROR(VLOOKUP(C41,'BD Total'!$A$1:$H$506,4,0),"") -> 9900 | G41: =IFERROR(F41*E41,"") -> 9900 | H41: =IFERROR(VLOOKUP(C41,'BD Total'!$A$1:$G$506,6,0),"") -> No | I41: =IFERROR(VLOOKUP(C41,'BD Total'!$A$1:$G$506,7,0),"") -> Si
B42: Electricidad | C42: Cableado 1,5 En Eva - Rollo 50m | D42: =IFERROR(VLOOKUP(C42,'BD Total'!$A$1:$H$506,3,0),"") -> Unidad | E42: 9 | F42: =IFERROR(VLOOKUP(C42,'BD Total'!$A$1:$H$506,4,0),"") -> 13105 | G42: =IFERROR(F42*E42,"") -> 117945 | H42: =IFERROR(VLOOKUP(C42,'BD Total'!$A$1:$G$506,6,0),"") -> No | I42: =IFERROR(VLOOKUP(C42,'BD Total'!$A$1:$G$506,7,0),"") -> Si
B43: Electricidad | C43: Cableado 2,5 En Eva - Rollo 50m | D43: =IFERROR(VLOOKUP(C43,'BD Total'!$A$1:$H$506,3,0),"") -> Unidad | E43: 9 | F43: =IFERROR(VLOOKUP(C43,'BD Total'!$A$1:$H$506,4,0),"") -> 17500 | G43: =IFERROR(F43*E43,"") -> 157500 | H43: =IFERROR(VLOOKUP(C43,'BD Total'!$A$1:$G$506,6,0),"") -> No | I43: =IFERROR(VLOOKUP(C43,'BD Total'!$A$1:$G$506,7,0),"") -> Si
B44: Electricidad | C44: Caja De Distribución | D44: =IFERROR(VLOOKUP(C44,'BD Total'!$A$1:$H$506,3,0),"") -> Unidad | E44: 80 | F44: =IFERROR(VLOOKUP(C44,'BD Total'!$A$1:$H$506,4,0),"") -> 800 | G44: =IFERROR(F44*E44,"") -> 64000 | H44: =IFERROR(VLOOKUP(C44,'BD Total'!$A$1:$G$506,6,0),"") -> No | I44: =IFERROR(VLOOKUP(C44,'BD Total'!$A$1:$G$506,7,0),"") -> Si
... B75: Piso | C75: Piso Vinilico Tipo Click 6 Mm | D75: =IFERROR(VLOOKUP(C75,'BD Total'!$A$1:$H$506,3,0),"") -> m2 | E75: 90 | F75: =IFERROR(VLOOKUP(C75,'BD Total'!$A$1:$H$506,4,0),"") -> 12596 | G75: =IFERROR(F75*E75,"") -> 1133640 | H75: =IFERROR(VLOOKUP(C75,'BD Total'!$A$1:$G$506,6,0),"") -> Si | I75: =IFERROR(VLOOKUP(C75,'BD Total'!$A$1:$G$506,7,0),"") -> Si
D76: =IFERROR(VLOOKUP(C76,'BD Total'!$A$1:$H$506,3,0),"") | F76: =IFERROR(VLOOKUP(C76,'BD Total'!$A$1:$H$506,4,0),"") | G76: =IFERROR(F76*E76,"") | H76: =IFERROR(VLOOKUP(C76,'BD Total'!$A$1:$G$506,6,0),"") | I76: =IFERROR(VLOOKUP(C76,'BD Total'!$A$1:$G$506,7,0),"")
B77: Piso | C77: Fragüe cerámico 1 kg | D77: =IFERROR(VLOOKUP(C77,'BD Total'!$A$1:$H$506,3,0),"") -> Unidad | E77: 3 | F77: =IFERROR(VLOOKUP(C77,'BD Total'!$A$1:$H$506,4,0),"") -> 1840.3361 | G77: =IFERROR(F77*E77,"") -> 5521.0084 | H77: =IFERROR(VLOOKUP(C77,'BD Total'!$A$1:$G$506,6,0),"") -> No | I77: =IFERROR(VLOOKUP(C77,'BD Total'!$A$1:$G$506,7,0),"") -> Si
B78: Puerta | C78: Chapa Puerta | D78: =IFERROR(VLOOKUP(C78,'BD Total'!$A$1:$H$506,3,0),"") -> Unidad | E78: 8 | F78: =IFERROR(VLOOKUP(C78,'BD Total'!$A$1:$H$506,4,0),"") -> 5000 | G78: =IFERROR(F78*E78,"") -> 40000 | H78: =IFERROR(VLOOKUP(C78,'BD Total'!$A$1:$G$506,6,0),"") -> Si | I78: =IFERROR(VLOOKUP(C78,'BD Total'!$A$1:$G$506,7,0),"") -> Si
B79: Puerta | C79: Puerta Enchapada Capri | D79: =IFERROR(VLOOKUP(C79,'BD Total'!$A$1:$H$506,3,0),"") -> Unidad | E79: 8 | F79: =IFERROR(VLOOKUP(C79,'BD Total'!$A$1:$H$506,4,0),"") -> 85000 | G79: =IFERROR(F79*E79,"") -> 680000 | H79: =IFERROR(VLOOKUP(C79,'BD Total'!$A$1:$G$506,6,0),"") -> Si | I79: =IFERROR(VLOOKUP(C79,'BD Total'!$A$1:$G$506,7,0),"") -> Si
B80: Puerta | C80: Bisagras | D80: =IFERROR(VLOOKUP(C80,'BD Total'!$A$1:$H$506,3,0),"") -> Unidad | E80: 8 | F80: =IFERROR(VLOOKUP(C80,'BD Total'!$A$1:$H$506,4,0),"") -> 3500 | G80: =IFERROR(F80*E80,"") -> 28000 | H80: =IFERROR(VLOOKUP(C80,'BD Total'!$A$1:$G$506,6,0),"") -> No | I80: =IFERROR(VLOOKUP(C80,'BD Total'!$A$1:$G$506,7,0),"") -> Si
B81: Puerta | C81: Puerta vidriada de 0,80 x 2,00 Termopanel PVC | D81: =IFERROR(VLOOKUP(C81,'BD Total'!$A$1:$H$506,3,0),"") -> Unidad | E81: 1 | F81: =IFERROR(VLOOKUP(C81,'BD Total'!$A$1:$H$506,4,0),"") -> 453782 | G81: =IFERROR(F81*E81,"") -> 453782 | H81: =IFERROR(VLOOKUP(C81,'BD Total'!$A$1:$G$506,6,0),"") -> Si | I81: =IFERROR(VLOOKUP(C81,'BD Total'!$A$1:$G$506,7,0),"") -> Si
B82: Puertas | C82: Marco Puerta | D82: =IFERROR(VLOOKUP(C82,'BD Total'!$A$1:$H$506,3,0),"") -> Unidad | E82: 8 | F82: =IFERROR(VLOOKUP(C82,'BD Total'!$A$1:$H$506,4,0),"") -> 11000 | G82: =IFERROR(F82*E82,"") -> 88000 | H82: =IFERROR(VLOOKUP(C82,'BD Total'!$A$1:$G$506,6,0),"") -> No | I82: =IFERROR(VLOOKUP(C82,'BD Total'!$A$1:$G$506,7,0),"") -> Si
...

Sheet 2 - Margenes Proyecto
B5: Tabla Costos Proyecto | F5: Tabla Comisiones | J5: Tabla Ganancias
B7: Costos Totales | C7: ='1 - Cotizador Personalizado'!G4 -> 39331406 | F7: =B9 -> Costo + Margen | G7: =C9 -> 51917456 | J7: =B8 -> Margen | K7: =C8 -> 12586050
B8: Margen | C8: =C7*D8 -> 12586050 | D8: 0.32 | F8: Comision Vendedor | G8: =G7*2.5% -> 1297936.4 | H8: =G8/G7 -> 0.025 | J8: =F10 -> Total Comisiones | K8: =G10 -> 1713276
B9: Costo + Margen | C9: =C7+C8 -> 51917456 | F9: Comision Supervisor | G9: =G7*0.8% -> 415339.65 | H9: =G9/G7 -> 0.008 | J9: Ganancia Real | K9: =K7-K8 -> 10872774
B10: IVA | C10: =C9*19% -> 9864316.6 | F10: Total Comisiones | G10: =SUM(G8:G9) -> 1713276
B11: Total Proyecto | C11: =C10+C9 -> 61781772

Sheet 3 - Impresión Personalizado
C1: Recuadro de Valores Proyecto
C3: Sub Totales | D3: ='2 - Margenes Proyecto'!C9 -> 51917456
C4: IVA | D4: ='2 - Margenes Proyecto'!C10 -> 9864316.6
C5: Total Proyecto | D5: ='2 - Margenes Proyecto'!C11 -> 61781772
A7: Cliente :
A8: Telefono :
A9: Dirección :
A10: *Tiempo de entrega entre 35 a 45 dias habiles.
A12: Categorias | B12: Item | C12: Unidad | D12: Cantidad
A13: Suma de Cantidad
D14: Total
A15: Adicionales | B15: Closet de Tres cuerpos - Piso a techo | C15: Unidad | D15: 3
B16: Conexión de Lavadora | C16: Unidad | D16: 1
B17: Gabinete para Calefont 11 litros | C17: Unidad | D17: 1
B18: Walking Closet 200 largo x 2,40 alto x 0,50 de profundidad | C18: Unidad | D18: 1
A19: Aislación | B19: Poliuretano Proyectado | C19: m2 | D19: 190
A20: Baño | B20: Angulo Aluminio 10x10 | C20: Unidad | D20: 6
B21: Columna de Ducha Baño mono mando | C21: Unidad | D21: 3
B22: Desagues Ducha | C22: Unidad | D22: 3
B23: Desgues Lavamos | C23: Unidad | D23: 3
B24: Espejo Redondo Retroiluminado 60 Diametro | C24: Unidad | D24: 3
B25: Kit Instalacion Sanitario Wc | C25: Unidad | D25: 3
B26: Mampara ajustable 6mm 135 -150x185cm | C26: Unidad | D26: 3
B27: Mueble Vanitorio 71 cm Fiumo Vessanti | C27: Unidad | D27: 3
B28: Porcelanato Blanco Brillante 60x60cm | C28: m2 | D28: 27
B29: Receptáculo 130x80 | C29: Unidad | D29: 3
B30: Teflon | C30: Unidad | D30: 3
B31: Tinta adheviso con pasta AC 25kg | C31: Unidad | D31: 8
B32: Volcanita Rh 12,5 | C32: Unidad | D32: 21
B33: Wc One Pice | C33: Unidad | D33: 3
A34: Cocina | B34: Lavaplatos Embutido | C34: Unidad | D34: 1
B35: Llave gas encimera | C35: Unidad | D35: 1
B36: Mueble de cocina Cub Cuarzo 3,20 mts + Aereo+Encimera+horno+Campana+ Isla Cuarzo | C36: Unidad | D36: 1
A37: Container | B37: Container Maritimo HC 12 x 2,44 x 2,89 - 40 Pies | C37: Unidad | D37: 3
A38: Electricidad | B38: Abrazaderas Metalicas | C38: Unidad | D38: 250
B39: Automatico 16 Amperes | C39: Unidad | D39: 1
B40: Automatico 25 Amperes | C40: Unidad | D40: 3
B41: Bipolar | C41: Unidad | D41: 1
B42: Cable 924 | C42: Unidad | D42: 1
B43: Cableado 1,5 En Eva - Rollo 50m | C43: Unidad | D43: 9
...

Sheet 4 - Impresión  Compras
D2: Recuadro de Valores Proyecto
D4: Sub Totales | F4: =SUM(F10:F1048576) -> 7815527.8
D5: IVA | F5: =F4*19% -> 1484950.3
A6: Nombre Cliente: | D6: Total Proyecto | F6: =F5+F4 -> 9300478.1
B7: ='3 - Impresión Personalizado'!B7 -> 0
A9: Categorias | B9: Item | C9: Unidad | D9: Cantidad | E9: P. Unitario | F9: P. Total
A11: Categorias | B11: Item | C11: Unidad | D11: Cantidad | E11: P. Unitario | F11: P. Total
A12: Baño | B12: Columna de Ducha Baño mono mando | C12: Unidad | D12: 1 | E12: 47000 | F12: 47000
B13: Mueble Vanitorio 71 cm Fiumo Vessanti | C13: Unidad | D13: 1 | E13: 137000 | F13: 137000
B14: Wc One Pice | C14: Unidad | D14: 1 | E14: 120000 | F14: 120000
B15: Angulo Aluminio 10x10 | C15: Unidad | D15: 4 | E15: 4700 | F15: 18800
B16: Espejo Redondo Retroiluminado 60 Diametro | C16: Unidad | D16: 1 | E16: 50000 | F16: 50000
B17: Extractor Aire baño 4" | C17: Unidad | D17: 1 | E17: 15957.983 | F17: 15957.983
B18: Mampara ajustable 6mm 135 -150x185cm | C18: Unidad | D18: 1 | E18: 179048.82 | F18: 179048.82
B19: Receptáculo 130x80 | C19: Unidad | D19: 1 | E19: 159000 | F19: 159000
B20: Fragüe cerámico 1 kg | C20: Unidad | D20: 2 | E20: 1840.3361 | F20: 3680.6723
B21: Porcelanato color Haya WF61515 15x60 cm | C21: m2 | D21: 9 | E21: 8394.958 | F21: 75554.622
B22: Tinta adheviso con pasta AC 25kg | C22: Unidad | D22: 1 | E22: 17638.655 | F22: 17638.655
B23: Barra Pasamano Muro 50cm | C23: Unidad | D23: 1 | E23: 9000 | F23: 9000
A24: (en blanco) | B24: (en blanco) | D24: (en blanco)
A25: Container | B25: Container Maritimo HC 12 x 2,44 x 2,89 - 40 Pies | C25: Unidad | D25: 1 | E25: 1950000 | F25: 1950000
A26: Aislación | B26: Poliuretano Proyectado 30 m2 | C26: Pack | D26: 1 | E26: 768000 | F26: 768000
A27: Cocina | B27: Lavaplatos Embutido | C27: Unidad | D27: 1 | E27: 82345 | F27: 82345
B28: Llave gas encimera | C28: Unidad | D28: 1 | E28: 22500 | F28: 22500
A29: Electricidad | B29: Abrazaderas Metalicas | C29: Unidad | D29: 100 | E29: 112 | F29: 11200
B30: Automatico 16 Amperes | C30: Unidad | D30: 1 | E30: 3500 | F30: 3500
B31: Caja 100 x 65 x 100 mm Estanca Blanco Mec | C31: Unidad | D31: 2 | E31: 2260.5042 | F31: 4521.0084
B32: Caja De Distribución | C32: Unidad | D32: 35 | E32: 800 | F32: 28000
B33: Cinta Aislante | C33: Unidad | D33: 1 | E33: 1200 | F33: 1200
B34: Conectores Conicos 1,5 | C34: Paquete | D34: 1 | E34: 5600 | F34: 5600
B35: Conectores Conicos 2,5 | C35: Paquete | D35: 1 | E35: 5600 | F35: 5600
B36: Conectores Terminales 20Mm | C36: Paquete | D36: 90 | E36: 370 | F36: 33300
B37: Diferenciales De 25 O 32 Amperes | C37: Unidad | D37: 4 | E37: 2000 | F37: 8000
B38: Enchufe Simple 16 ap | C38: Unidad | D38: 2 | E38: 2460 | F38: 4920
B39: Enchufes Dobles | C39: Unidad | D39: 12 | E39: 3000 | F39: 36000
B40: Enchufes Dobles Ip65 | C40: Unidad | D40: 1 | E40: 11000 | F40: 11000
B41: Fruler 1,5 | C41: Paquete | D41: 1 | E41: 1300 | F41: 1300
... B54: Caja estanca exterior | C54: Unidad | D54: 2 | E54: 1500 | F54: 3000
A55: Grifería | B55: Llaves Monomando - Lava Manos | C55: Unidad | D55: 1 | E55: 15000 | F55: 15000
A56: Pintura | B56: Barniz Cerestain | C56: Galon | D56: 1 | E56: 25000 | F56: 25000
...
